Workbook

Sheet Groups
B1: Groups (US Eastern Time)
B3: Group A | E3: Group B | H3: Group C | K3: Group D | N3: Group E | Q3: Group F
B4: Mexico | E4: Canada | H4: Brazil | K4: USA | N4: Germany | Q4: Netherlands
B5: South Africa | E5: Bosnia-Herzegovina | H5: Morocco | K5: Paraguay | N5: Curacao | Q5: Japan
B6: South Korea | E6: Qatar | H6: Haiti | K6: Australia | N6: Côte d'Ivoire | Q6: Sweden
B7: Czechia | E7: Switzerland | H7: Scotland | K7: Türkiye | N7: Ecuador | Q7: Tunisia
B9: Mexico City | E9: Toronto | H9: New York / New Jersy | K9: Los Angeles | N9: Houston | Q9: Dallas
B10: 46184 | C10: 0.625 | E10: 46185 | F10: 0.625 | H10: Sat, 6.13.2026 | I10: 0.75 | K10: Fri, 6.12.2026 | L10: 0.875 | N10: 46187 | O10: 0.54166667 | Q10: 46187 | R10: 0.66666667
B11: Mexico | C11: South Africa | E11: Canada | F11: Bosnia-Herzegovina | H11: Brazil | I11: Morocco | K11: USA | L11: Paraguay | N11: Germany | O11: Curacao | Q11: Netherlands | R11: Japan
B14: Guadalajara | E14: San Francisco Bay Area | H14: Boston | K14: Vancouver | N14: Philadelphia | Q14: Monterrey
B15: Thu, 6.11.2026 | C15: 0.91666667 | E15: 46186 | F15: 0.625 | H15: Sat, 6.13.2026 | I15: 0.875 | K15: Sat, 6.13.2026 | L15: 0 | N15: Sun, 6.14.2026 | O15: 0.79166667 | Q15: Sun, 6.14.2026 | R15: 0.91666667
B16: South Korea | C16: Czechia | E16: Qatar | F16: Switzerland | H16: Haiti | I16: Scotland | K16: Australia | L16: Türkiye | N16: Côte d'Ivoire | O16: Ecuador | Q16: Sweden | R16: Tunisia
B19: Atlanta | E19: Los Angeles | H19: Boston | K19: Seattle | N19: Toronto | Q19: Houston
B20: 46191 | C20: 0.5 | E20: 46191 | F20: 0.625 | H20: Fri, 6.19.2026 | I20: 0.75 | K20: 46192 | L20: 0.625 | N20: 46193 | O20: 0.66666667 | Q20: 46193 | R20: 0.54166667
B21: Czechia | C21: South Africa | E21: Switzerland | F21: Bosnia-Herzegovina | H21: Scotland | I21: Morocco | K21: USA | L21: Australia | N21: Germany | O21: Côte d'Ivoire | Q21: Netherlands | R21: Sweden
B24: Guadalajara | E24: Vancouver | H24: Philadelphia | K24: San Francisco Bay Area | N24: Kansas City | Q24: Monterrey
B25: Thu, 6.18.2026 | C25: 0.875 | E25: Thu, 6.18.2026 | F25: 0.75 | H25: Fri, 6.19.2026 | I25: 0.875 | K25: Fri, 6.19.2026 | L25: 0 | N25: Sat, 6.20.2026 | O25: 0.83333333 | Q25: Sat, 6.20.2026 | R25: 0
B26: Mexico | C26: South Korea | E26: Canada | F26: Qatar | H26: Brazil | I26: Haiti | K26: Türkiye | L26: Paraguay | N26: Ecuador | O26: Curacao | Q26: Tunisia | R26: Japan
B29: Mexico City | E29: Vancouver | H29: Miami | K29: Los Angeles | N29: Philadelphia | Q29: Dallas
B30: Wed, 6.24.2026 | C30: 0.875 | E30: 46197 | F30: 0.625 | H30: Wed, 6.24.2026 | I30: 0.75 | K30: Thu, 6.25.2026 | L30: 0.91666667 | N30: 46198 | O30: 0.66666667 | Q30: Thu, 6.25.2026 | R30: 0.79166667
B31: Czechia | C31: Mexico | E31: Switzerland | F31: Canada | H31: Scotland | I31: Brazil | K31: Türkiye | L31: USA | N31: Curacao | O31: Côte d'Ivoire | Q31: Japan | R31: Sweden
B34: Monterrey | E34: Seattle | H34: Atlanta | K34: San Francisco Bay Area | N34: New York / New Jersy | Q34: Kansas City
B35: Wed, 6.24.2026 | C35: 0.875 | E35: 46197 | F35: 0.625 | H35: Wed, 6.24.2026 | I35: 0.75 | K35: Thu, 6.25.2026 | L35: 0.91666667 | N35: 46198 | O35: 0.66666667 | Q35: Thu, 6.25.2026 | R35: 0.79166667
B36: South Africa | C36: South Korea | E36: Bosnia-Herzegovina | F36: Qatar | H36: Morocco | I36: Haiti | K36: Paraguay | L36: Australia | N36: Ecuador | O36: Germany | Q36: Tunisia | R36: Netherlands
B39: Final Standings | E39: Final Standings | H39: Final Standings | K39: Final Standings | N39: Final Standings | Q39: Final Standings
A40: 1. | D40: 1. | G40: 1. | J40: 1. | M40: 1. | P40: 1.
A41: 2. | D41: 2. | G41: 2. | J41: 2. | M41: 2. | P41: 2.
A42: 3. | D42: 3. | G42: 3. | J42: 3. | M42: 3. | P42: 3.
A43: 4. | D43: 4. | G43: 4. | J43: 4. | M43: 4. | P43: 4.
B45: Group G | E45: Group H | H45: K | K45: Group J | N45: Group K | Q45: Group L
B46: Belgium | E46: Spain | H46: France | K46: Argentina | N46: Portugal | Q46: England
B47: Egypt | E47: Cabo Verde | H47: Senegal | K47: Algeria | N47: Congo DR | Q47: Croatia
B48: IR Iran | E48: Saudi Arabia | H48: Iraq | K48: Austria | N48: Uzbekistan | Q48: Ghana
B49: New Zealand | E49: Uruguay | H49: Norway | K49: Jordan | N49: Colombia | Q49: Panama
B51: Seattle | E51: Atlanta | H51: New York / New Jersy | K51: Kansas City | N51: Houston | Q51: Dallas
B52: 46188 | C52: 0.625 | E52: 46188 | F52: 0.5 | H52: 46189 | I52: 0.625 | K52: Tue, 6.16.2026 | L52: 0.875 | N52: 46190 | O52: 0.54166667 | Q52: 46190 | R52: 0.66666667
B53: Belgium | C53: Egypt | E53: Spain | F53: Cabo Verde | H53: France | I53: Senegal | K53: Argentina | L53: Algeria | N53: Portugal | O53: Congo DR | Q53: England | R53: Croatia
B56: Los Angeles | E56: Miami | H56: Boston | K56: San Francisco Bay Area | N56: Mexico City | Q56: Toronto
B57: Mon, 6.15.2026 | C57: 0.875 | E57: Mon, 6.15.2026 | F57: 0.75 | H57: Tue, 6.16.2026 | I57: 0.75 | K57: Tue, 6.16.2026 | L57: 0 | N57: Wed, 6.17.2026 | O57: 0.91666667 | Q57: Wed, 6.17.2026 | R57: 0.79166667
B58: IR Iran | C58: New Zealand | E58: Saudi Arabia | F58: Uruguay | H58: Iraq | I58: Norway | K58: Austria | L58: Jordan | N58: Uzbekistan | O58: Colombia | Q58: Ghana | R58: Panama
...

Sheet Round of 32
B1: Round of 32 (US Eastern Time)
A3: 73 | B3: Round of 32 / 1 | D3: 76 | E3: Round of 32 / 2 | G3: 74 | H3: Round of 32 / 3 | J3: 75 | K3: Round of 32 / 4
B4: Los Angeles | E4: Houston | H4: Boston | K4: Monterrey
B5: 46201 | C5: 0.625 | E5: 46202 | F5: 0.54166667 | H5: 46202 | I5: 0.6875 | K5: Mon, 6.29.2026 | L5: 0.875
B6: =IF(Groups!B41<>"",Groups!B41,"") | C6: =IF(Groups!E41<>"",Groups!E41,"") | E6: =IF(Groups!H40<>"",Groups!H40,"") | F6: =IF(Groups!Q41<>"",Groups!Q41,"") | H6: =IF(Groups!N40<>"",Groups!N40,"") | K6: =IF(Groups!Q40<>"",Groups!Q40,"") | L6: =IF(Groups!H41<>"",Groups!H41,"")
B8: 2. Gr. A | C8: 2. Gr. B | E8: 1. Gr. C | F8: 2. Gr. F | H8: 1. Gr. E | I8: * | K8: 1. Gr. F | L8: 2. Gr. C
A10: 78 | B10: Round of 32 / 5 | D10: 77 | E10: Round of 32 / 6 | G10: 79 | H10: Round of 32 / 7 | J10: 80 | K10: Round of 32 / 8
B11: Dallas | E11: New York / New Jersey | H11: Mexico City | K11: Atlanta
B12: 46203 | C12: 0.54166667 | E12: 46203 | F12: 0.70833333 | H12: Tue, 6.30.2026 | I12: 0.875 | K12: 46204 | L12: 0.5
B13: =IF(Groups!N41<>"",Groups!N41,"") | C13: =IF(Groups!H83<>"",Groups!H83,"") | E13: =IF(Groups!H82<>"",Groups!H82,"") | H13: =IF(Groups!B40<>"",Groups!B40,"") | K13: =IF(Groups!Q82<>"",Groups!Q82,"")
B15: 2. Gr. E | C15: 2. Gr. I | E15: 1. Gr. I | F15: * | H15: 1. Gr. A | I15: * | K15: 1. Gr. L | L15: *
A17: 82 | B17: Round of 32 / 9 | D17: 81 | E17: Round of 32 / 10 | G17: 84 | H17: Round of 32 / 11 | J17: 83 | K17: Round of 32/ 12
B18: Seattle | E18: San Francisco Bay Area | H18: Los Angeles | K18: Toronto
B19: 46204 | C19: 0.66666667 | E19: Wed, 7.1.2026 | F19: 0.83333333 | H19: 46205 | I19: 0.625 | K19: Thu, 7.2.2026 | L19: 0.79166667
B20: =IF(Groups!B82<>"",Groups!B82,"") | E20: =IF(Groups!K40<>"",Groups!K40,"") | H20: =IF(Groups!E82<>"",Groups!E82,"") | I20: =IF(Groups!K83<>"",Groups!K83,"") | K20: =IF(Groups!N83<>"",Groups!N83,"") | L20: =IF(Groups!Q83<>"",Groups!Q83,"")
B22: 1. Gr. G | C22: * | E22: 1. Gr. D | F22: * | H22: 1. Gr. H | I22: 2. Gr. J | K22: 2. Gr. K | L22: 2. Gr. L
A24: 85 | B24: Round of 32/ 13 | D24: 88 | E24: Round of 32 / 14 | G24: 86 | H24: Round of 32 / 15 | J24: 87 | K24: Round of 32 / 16
B25: Vancouver | E25: Dallas | H25: Miami | K25: Kansas City
B26: Thu, 7.2.2026 | C26: 0.95833333 | E26: 46206 | F26: 0.58333333 | H26: 46207 | I26: 0.75 | K26: Fri, 7.3.2026 | L26: 0.89583333
B27: =IF(Groups!E40<>"",Groups!E40,"") | E27: =IF(Groups!K41<>"",Groups!K41,"") | F27: =IF(Groups!B83<>"",Groups!B83,"") | H27: =IF(Groups!K82<>"",Groups!K82,"") | I27: =IF(Groups!E83<>"",Groups!E83,"") | K27: =IF(Groups!N82<>"",Groups!N82,"")
B29: 1. Gr. B | C29: * | E29: 2. Gr. D | F29: 2. Gr. G | H29: 1. Gr. J | I29: 2. Gr. H | K29: 1. Gr. K | L29: *
B32: * | C32: The top 8 third-place finishers also qualify

Sheet Round of 16,8,4, semi, final
B1: Round of 16, 8, 4 and final (US Eastern Time)
A3: 89 | B3: Round of 16 / 2 | D3: 90 | E3: Round of 16 / 1 | G3: 93 | H3: Round of 16 / 5 | J3: 94 | K3: Round of 16 / 6 | M3: 91 | N3: Round of 16 / 3 | P3: 92 | Q3: Round of 16 / 4 | S3: 95 | T3: Round of 16 / 7 | V3: 96 | W3: Round of 16 / 8
B4: Philadelphia | E4: Houston | H4: Dallas | K4: Seattle | N4: New York / New Jersey | Q4: Mexico City | T4: Atlanta | W4: Vancouver
B5: 46207 | C5: 0.70833333 | E5: 46207 | F5: 0.54166667 | H5: 46209 | I5: 0.625 | K5: Mon, 7.6.2026 | L5: 0.83333333 | N5: 46208 | O5: 0.66666667 | Q5: Sun, 7.5.2026 | R5: 0.83333333 | T5: 46210 | U5: 0.5 | W5: 46210 | X5: 0.66666667
B6: =IF(OR('Round of 32'!H7="",'Round of 32'!I7=""),"",IF('Round of 32'!H7>'Round of 32'!I7,'Round of 32'!H6,'Round of 32'!I6)) | C6: =IF(OR('Round of 32'!E14="",'Round of 32'!F14=""),"",IF('Round of 32'!E14>'Round of 32'!F14,'Round of 32'!E13,'Round of 32'!F13)) | E6: =IF(OR('Round of 32'!B7="",'Round of 32'!C7=""),"",IF('Round of 32'!B7>'Round of 32'!C7,'Round of 32'!B6,'Round of 32'!C6)) | F6: =IF(OR('Round of 32'!K7="",'Round of 32'!L7=""),"",IF('Round of 32'!K7>'Round of 32'!L7,'Round of 32'!K6,'Round of 32'!L6)) | H6: =IF(OR('Round of 32'!K21="",'Round of 32'!L21=""),"",IF('Round of 32'!K21>'Round of 32'!L21,'Round of 32'!K20,'Round of 32'!L20)) | I6: =IF(OR('Round of 32'!H21="",'Round of 32'!I21=""),"",IF('Round of 32'!H21>'Round of 32'!I21,'Round of 32'!H20,'Round of 32'!I20)) | K6: =IF(OR('Round of 32'!E21="",'Round of 32'!F21=""),"",IF('Round of 32'!E21>'Round of 32'!F21,'Round of 32'!E20,'Round of 32'!F20)) | L6: =IF(OR('Round of 32'!B21="",'Round of 32'!C21=""),"",IF('Round of 32'!B21>'Round of 32'!C21,'Round of 32'!B20,'Round of 32'!C20)) | N6: =IF(OR('Round of 32'!E7="",'Round of 32'!F7=""),"",IF('Round of 32'!E7>'Round of 32'!F7,'Round of 32'!E6,'Round of 32'!F6)) | O6: =IF(OR('Round of 32'!B14="",'Round of 32'!C14=""),"",IF('Round of 32'!B14>'Round of 32'!C14,'Round of 32'!B13,'Round of 32'!C13)) | Q6: =IF(OR('Round of 32'!H14="",'Round of 32'!I14=""),"",IF('Round of 32'!H14>'Round of 32'!I14,'Round of 32'!H13,'Round of 32'!I13)) | R6: =IF(OR('Round of 32'!K14="",'Round of 32'!L14=""),"",IF('Round of 32'!K14>'Round of 32'!L14,'Round of 32'!K13,'Round of 32'!L13)) | T6: =IF(OR('Round of 32'!H28="",'Round of 32'!I28=""),"",IF('Round of 32'!H28>'Round of 32'!I28,'Round of 32'!H27,'Round of 32'!I27)) | U6: =IF(OR('Round of 32'!E28="",'Round of 32'!F28=""),"",IF('Round of 32'!E28>'Round of 32'!F28,'Round of 32'!E27,'Round of 32'!F27)) | W6: =IF(OR('Round of 32'!B28="",'Round of 32'!C28=""),"",IF('Round of 32'!B28>'Round of 32'!C28,'Round of 32'!B27,'Round of 32'!C27)) | X6: =IF(OR('Round of 32'!K28="",'Round of 32'!L28=""),"",IF('Round of 32'!K28>'Round of 32'!L28,'Round of 32'!K27,'Round of 32'!L27))
B8: Winner 74 | C8: Winner 77 | E8: Winner 73 | F8: Winner 75 | H8: Winner 83 | I8: Winner 84 | K8: Winner 81 | L8: Winner 82 | N8: Winner 76 | O8: Winner 78 | Q8: Winner 79 | R8: Winner 80 | T8: Winner 86 | U8: Winner 88 | W8: Winner 85 | X8: Winner 87
B10: 97 | C10: Round of 8 / 1 | H10: 98 | I10: Round of 8 / 2 | N10: 99 | O10: Round of 8 / 3 | T10: 100 | U10: Round of 8 / 4
C11: Boston | I11: Los Angeles | O11: Miami | U11: Kansas City
C12: 46212 | E12: 0.66666667 | I12: 46213 | K12: 0.625 | O12: 46214 | Q12: 0.70833333 | U12: Sat, 7.11.2026 | W12: 0.875
C13: =IF(OR(B7="",C7=""),"",IF(B7>C7,B6,C6)) | E13: =IF(OR(E7="",F7=""),"",IF(E7>F7,E6,F6)) | I13: =IF(OR(H7="",I7=""),"",IF(H7>I7,H6,I6)) | K13: =IF(OR(K7="",L7=""),"",IF(K7>L7,K6,L6)) | O13: =IF(OR(N7="",O7=""),"",IF(N7>O7,N6,O6)) | Q13: =IF(OR(Q7="",R7=""),"",IF(Q7>R7,Q6,R6)) | U13: =IF(OR(T7="",U7=""),"",IF(T7>U7,T6,U6)) | W13: =IF(OR(W7="",X7=""),"",IF(W7>X7,W6,X6))
D14: : | J14: : | P14: : | V14: :
C15: Winner 89 | E15: Winner 90 | I15: Winner 93 | K15: Winner 94 | O15: Winner 91 | Q15: Winner 92 | U15: Winner 95 | W15: Winner 96
E18: 101 | F18: Round of 4 / 1 | K18: 103 | L18: Third place match | Q18: 102 | R18: Round of 4 / 2
F19: Dallas | L19: Miami | R19: Atlanta
F20: 45852 | H20: 0.625 | L20: 46221 | N20: 0.70833333 | R20: 46218 | T20: 0.625
F21: =IF(OR(C14="",E14=""),"",IF(C14>E14,C13,E13)) | H21: =IF(OR(I14="",K14=""),"",IF(I14>K14,I13,K13)) | L21: =IF(OR(F22="",H22=""),"",IF(F22<H22,F21,H21)) | N21: =IF(OR(R22="",T22=""),"",IF(R22<T22,R21,T21)) | R21: =IF(OR(O14="",Q14=""),"",IF(O14>Q14,O13,Q13)) | T21: =IF(OR(U14="",W14=""),"",IF(U14>W14,U13,W13))
G22: : | M22: : | S22: :
F23: Winner 97 | H23: Winner 98 | L23: Verlierer 101 | N23: Verlierer 102 | R23: Winner 99 | T23: Winner 100
K26: 104 | L26: Final
L27: New York / New Jersey
L28: 46222 | N28: 0.625
L29: =IF(OR(F22="",H22=""),"",IF(F22>H22,F21,H21)) | N29: =IF(OR(R22="",T22=""),"",IF(R22>T22,R21,T21))
M30: :
L31: Winner 101 | N31: Winner 102
